Workbook

Sheet Supuestos
A1: GEINSTAL - Modelo de Rentabilidad por Cliente
A2: Mantenimiento Integral de Edificios
A4: DATOS DE EMPRESA
A5: Empleados totales | B5: 305
A6: Facturación total (€) | B6: 35000000
A7: Coste medio técnico (€/año) | B7: 35000
A9: SUPUESTOS POR CLIENTE
A10: Cliente | B10: Ingresos Anuales (€) | C10: Técnicos Asignados | D10: Coste Técnico (€/año) | E10: Coste Personal Total (€/año) | F10: Material Estimado (€/año) | G10: Coste Directo Total (€/año) | H10: % Horas Extra Urgencias | I10: Coste Urgencias (€/año)
A11: Hospital Vall d'Hebron | B11: 450000 | C11: 8 | D11: 35000 | E11: =C11*D11 -> 280000 | F11: 45000 | G11: =E11+F11 -> 325000 | H11: 0.08 | I11: =E11*H11 -> 22400
A12: SEAT Martorell | B12: 280000 | C12: 4 | D12: 35000 | E12: =C12*D12 -> 140000 | F12: 30000 | G12: =E12+F12 -> 170000 | H12: 0.15 | I12: =E12*H12 -> 21000
A13: UAB Bellaterra | B13: 180000 | C13: 3 | D13: 35000 | E13: =C13*D13 -> 105000 | F13: 15000 | G13: =E13+F13 -> 120000 | H13: 0.03 | I13: =E13*H13 -> 3150
A14: Danone Parets | B14: 120000 | C14: 2 | D14: 35000 | E14: =C14*D14 -> 70000 | F14: 10000 | G14: =E14+F14 -> 80000 | H14: 0.05 | I14: =E14*H14 -> 3500
A15: CCCB Barcelona | B15: 95000 | C15: 1 | D15: 35000 | E15: =C15*D15 -> 35000 | F15: 8000 | G15: =E15+F15 -> 43000 | H15: 0.02 | I15: =E15*H15 -> 700
A16: TOTAL | B16: =SUM(B11:B15) -> 1125000 | C16: =SUM(C11:C15) -> 18 | E16: =SUM(E11:E15) -> 630000 | F16: =SUM(F11:F15) -> 108000 | G16: =SUM(G11:G15) -> 738000 | I16: =SUM(I11:I15) -> 50750
A18: PARÁMETROS GENERALES
A19: % Gastos estructura s/ingresos | B19: 0.12
A20: % Gastos comerciales s/ingresos | B20: 0.05
A21: % Otros gastos indirectos s/ingresos | B21: 0.03
A22: % Total gastos indirectos | B22: =B19+B20+B21 -> 0.2
A24: NOTAS
A25: • Valores en azul son inputs modificables (hardcoded)
A26: • Los gastos indirectos se asignan proporcionalmente a los ingresos de cada cliente
A27: • El coste de personal incluye salario bruto + SS empresa (coste empresa total)

Sheet Modelo
A1: GEINSTAL - Análisis de Rentabilidad por Cliente (Mensual)
A2: Todos los valores en €/mes. Fórmulas vinculadas a pestaña Supuestos.
A4: INGRESOS MENSUALES
A5: Cliente | B5: Vall d'Hebron | C5: SEAT | D5: UAB | E5: Danone | F5: CCCB | G5: TOTAL
A6: Ingresos contrato | B6: =Supuestos!B11/12 -> 37500 | C6: =Supuestos!B12/12 -> 23333.333 | D6: =Supuestos!B13/12 -> 15000 | E6: =Supuestos!B14/12 -> 10000 | F6: =Supuestos!B15/12 -> 7916.6667 | G6: =SUM(B6:F6) -> 93750
A8: COSTES DIRECTOS MENSUALES
A9: Coste personal | B9: =Supuestos!E11/12 -> 23333.333 | C9: =Supuestos!E12/12 -> 11666.667 | D9: =Supuestos!E13/12 -> 8750 | E9: =Supuestos!E14/12 -> 5833.3333 | F9: =Supuestos!E15/12 -> 2916.6667 | G9: =SUM(B9:F9) -> 52500
A10: Coste material | B10: =Supuestos!F11/12 -> 3750 | C10: =Supuestos!F12/12 -> 2500 | D10: =Supuestos!F13/12 -> 1250 | E10: =Supuestos!F14/12 -> 833.33333 | F10: =Supuestos!F15/12 -> 666.66667 | G10: =SUM(B10:F10) -> 9000
A11: Coste urgencias | B11: =Supuestos!I11/12 -> 1866.6667 | C11: =Supuestos!I12/12 -> 1750 | D11: =Supuestos!I13/12 -> 262.5 | E11: =Supuestos!I14/12 -> 291.66667 | F11: =Supuestos!I15/12 -> 58.333333 | G11: =SUM(B11:F11) -> 4229.1667
A12: Total costes directos | B12: =B9+B10+B11 -> 28950 | C12: =C9+C10+C11 -> 15916.667 | D12: =D9+D10+D11 -> 10262.5 | E12: =E9+E10+E11 -> 6958.3333 | F12: =F9+F10+F11 -> 3641.6667 | G12: =SUM(B12:F12) -> 65729.167
A14: MARGEN BRUTO
A15: Margen bruto (€) | B15: =B6-B12 -> 8550 | C15: =C6-C12 -> 7416.6667 | D15: =D6-D12 -> 4737.5 | E15: =E6-E12 -> 3041.6667 | F15: =F6-F12 -> 4275 | G15: =SUM(B15:F15) -> 28020.833
A16: Margen bruto (%) | B16: =IF(B6=0,0,B15/B6) -> 0.228 | C16: =IF(C6=0,0,C15/C6) -> 0.31785714 | D16: =IF(D6=0,0,D15/D6) -> 0.31583333 | E16: =IF(E6=0,0,E15/E6) -> 0.30416667 | F16: =IF(F6=0,0,F15/F6) -> 0.54 | G16: =IF(G6=0,0,G15/G6) -> 0.29888889
A18: COSTES INDIRECTOS ASIGNADOS
A19: Gastos estructura | B19: =B6*Supuestos!$B$19 -> 4500 | C19: =C6*Supuestos!$B$19 -> 2800 | D19: =D6*Supuestos!$B$19 -> 1800 | E19: =E6*Supuestos!$B$19 -> 1200 | F19: =F6*Supuestos!$B$19 -> 950 | G19: =SUM(B19:F19) -> 11250
A20: Gastos comerciales | B20: =B6*Supuestos!$B$20 -> 1875 | C20: =C6*Supuestos!$B$20 -> 1166.6667 | D20: =D6*Supuestos!$B$20 -> 750 | E20: =E6*Supuestos!$B$20 -> 500 | F20: =F6*Supuestos!$B$20 -> 395.83333 | G20: =SUM(B20:F20) -> 4687.5
A21: Otros gastos indirectos | B21: =B6*Supuestos!$B$21 -> 1125 | C21: =C6*Supuestos!$B$21 -> 700 | D21: =D6*Supuestos!$B$21 -> 450 | E21: =E6*Supuestos!$B$21 -> 300 | F21: =F6*Supuestos!$B$21 -> 237.5 | G21: =SUM(B21:F21) -> 2812.5
A22: Total costes indirectos | B22: =B19+B20+B21 -> 7500 | C22: =C19+C20+C21 -> 4666.6667 | D22: =D19+D20+D21 -> 3000 | E22: =E19+E20+E21 -> 2000 | F22: =F19+F20+F21 -> 1583.3333 | G22: =SUM(B22:F22) -> 18750
A24: MARGEN NETO
A25: Margen neto (€) | B25: =B15-B22 -> 1050 | C25: =C15-C22 -> 2750 | D25: =D15-D22 -> 1737.5 | E25: =E15-E22 -> 1041.6667 | F25: =F15-F22 -> 2691.6667 | G25: =SUM(B25:F25) -> 9270.8333
A26: Margen neto (%) | B26: =IF(B6=0,0,B25/B6) -> 0.028 | C26: =IF(C6=0,0,C25/C6) -> 0.11785714 | D26: =IF(D6=0,0,D25/D6) -> 0.11583333 | E26: =IF(E6=0,0,E25/E6) -> 0.10416667 | F26: =IF(F6=0,0,F25/F6) -> 0.34 | G26: =IF(G6=0,0,G25/G6) -> 0.098888889
A28: CHECK DE CUADRE
A29: Concepto | B29: Modelo (mensual) | C29: Supuestos (anual/12) | D29: Diferencia | E29: Estado
A30: Ingresos totales | B30: =G6 -> 93750 | C30: =Supuestos!B16/12 -> 93750 | D30: =B30-C30 -> 0 | E30: =IF(ABS(D30)<0.01,"✅ OK","❌ ERROR") -> ✅ OK
A31: Costes directos totales (incl. urgencias) | B31: =G12 -> 65729.167 | C31: =(Supuestos!G16+Supuestos!I16)/12 -> 65729.167 | D31: =B31-C31 -> 0 | E31: =IF(ABS(D31)<0.01,"✅ OK","❌ ERROR") -> ✅ OK
A32: Margen neto = Ingresos - CD - CI | B32: =G25 -> 9270.8333 | C32: =G6-G12-G22 -> 9270.8333 | D32: =B32-C32 -> 0 | E32: =IF(ABS(D32)<0.01,"✅ OK","❌ ERROR") -> ✅ OK
A33: % Indirectos aplicado | B33: =IF(G6=0,0,G22/G6) -> 0.2 | C33: =Supuestos!B22 -> 0.2 | D33: =B33-C33 -> 0 | E33: =IF(ABS(D33)<0.0001,"✅ OK","❌ ERROR") -> ✅ OK
B35: Vall d'Hebron | C35: SEAT | D35: UAB | E35: Danone | F35: CCCB
A36: Margen Bruto % | B36: =B16 -> 0.228 | C36: =C16 -> 0.31785714 | D36: =D16 -> 0.31583333 | E36: =E16 -> 0.30416667 | F36: =F16 -> 0.54
A37: Margen Neto % (sin urgencias) | B37: =IF(B6=0,0,(B6-(B9+B10)-B22)/B6) -> 0.077777778 | C37: =IF(C6=0,0,(C6-(C9+C10)-C22)/C6) -> 0.19285714 | D37: =IF(D6=0,0,(D6-(D9+D10)-D22)/D6) -> 0.13333333 | E37: =IF(E6=0,0,(E6-(E9+E10)-E22)/E6) -> 0.13333333 | F37: =IF(F6=0,0,(F6-(F9+F10)-F22)/F6) -> 0.34736842
A38: Margen Neto Ajustado % | B38: =B26 -> 0.028 | C38: =C26 -> 0.11785714 | D38: =D26 -> 0.11583333 | E38: =E26 -> 0.10416667 | F38: =F26 -> 0.34

Sheet Forecast
A1: GEINSTAL - Forecast 12 meses y Análisis de Escenarios
A2: Proyección del margen neto por cliente y consolidado. Factores modificables en azul.
A4: FACTORES DE ESCENARIO
A5: Parámetro | B5: Base | C5: Optimista | D5: Pesimista | E5: Notas
A6: Factor ingresos | B6: 1 | C6: 1.08 | D6: 0.95 | E6: Aplicado a ingresos base mensuales
A7: Factor costes directos | B7: 1 | C7: 0.95 | D7: 1.1 | E7: Personal + material (sin urgencias)
A8: Factor horas extra urgencias | B8: 1 | C8: 0.5 | D8: 2 | E8: Multiplicador sobre coste urgencias base
A9: Crecimiento mensual (compuesto) | B9: 0 | C9: 0.005 | D9: -0.003 | E9: Crecimiento mes a mes aplicado a ingresos
A11: PROYECCIÓN 12 MESES - MARGEN NETO CONSOLIDADO POR ESCENARIO
A12: Escenario / Mes | B12: M1 | C12: M2 | D12: M3 | E12: M4 | F12: M5 | G12: M6 | H12: M7 | I12: M8 | J12: M9 | K12: M10 | L12: M11 | M12: M12 | N12: Total Año
A13: Base | B13: =Modelo!$G$6*$B$6*(1+$B$9)^0 - (Modelo!$G$9+Modelo!$G$10)*$B$7 - Modelo!$G$11*$B$8 - (Modelo!$G$6*$B$6*(1+$B$9)^0)*Supuestos!$B$22 -> 9270.8333 | C13: =Modelo!$G$6*$B$6*(1+$B$9)^1 - (Modelo!$G$9+Modelo!$G$10)*$B$7 - Modelo!$G$11*$B$8 - (Modelo!$G$6*$B$6*(1+$B$9)^1)*Supuestos!$B$22 -> 9270.8333 | D13: =Modelo!$G$6*$B$6*(1+$B$9)^2 - (Modelo!$G$9+Modelo!$G$10)*$B$7 - Modelo!$G$11*$B$8 - (Modelo!$G$6*$B$6*(1+$B$9)^2)*Supuestos!$B$22 -> 9270.8333 | E13: =Modelo!$G$6*$B$6*(1+$B$9)^3 - (Modelo!$G$9+Modelo!$G$10)*$B$7 - Modelo!$G$11*$B$8 - (Modelo!$G$6*$B$6*(1+$B$9)^3)*Supuestos!$B$22 -> 9270.8333 | F13: =Modelo!$G$6*$B$6*(1+$B$9)^4 - (Modelo!$G$9+Modelo!$G$10)*$B$7 - Modelo!$G$11*$B$8 - (Modelo!$G$6*$B$6*(1+$B$9)^4)*Supuestos!$B$22 -> 9270.8333 | G13: =Modelo!$G$6*$B$6*(1+$B$9)^5 - (Modelo!$G$9+Modelo!$G$10)*$B$7 - Modelo!$G$11*$B$8 - (Modelo!$G$6*$B$6*(1+$B$9)^5)*Supuestos!$B$22 -> 9270.8333 | H13: =Modelo!$G$6*$B$6*(1+$B$9)^6 - (Modelo!$G$9+Modelo!$G$10)*$B$7 - Modelo!$G$11*$B$8 - (Modelo!$G$6*$B$6*(1+$B$9)^6)*Supuestos!$B$22 -> 9270.8333 | I13: =Modelo!$G$6*$B$6*(1+$B$9)^7 - (Modelo!$G$9+Modelo!$G$10)*$B$7 - Modelo!$G$11*$B$8 - (Modelo!$G$6*$B$6*(1+$B$9)^7)*Supuestos!$B$22 -> 9270.8333 | J13: =Modelo!$G$6*$B$6*(1+$B$9)^8 - (Modelo!$G$9+Modelo!$G$10)*$B$7 - Modelo!$G$11*$B$8 - (Modelo!$G$6*$B$6*(1+$B$9)^8)*Supuestos!$B$22 -> 9270.8333 | K13: =Modelo!$G$6*$B$6*(1+$B$9)^9 - (Modelo!$G$9+Modelo!$G$10)*$B$7 - Modelo!$G$11*$B$8 - (Modelo!$G$6*$B$6*(1+$B$9)^9)*Supuestos!$B$22 -> 9270.8333 | L13: =Modelo!$G$6*$B$6*(1+$B$9)^10 - (Modelo!$G$9+Modelo!$G$10)*$B$7 - Modelo!$G$11*$B$8 - (Modelo!$G$6*$B$6*(1+$B$9)^10)*Supuestos!$B$22 -> 9270.8333 | M13: =Modelo!$G$6*$B$6*(1+$B$9)^11 - (Modelo!$G$9+Modelo!$G$10)*$B$7 - Modelo!$G$11*$B$8 - (Modelo!$G$6*$B$6*(1+$B$9)^11)*Supuestos!$B$22 -> 9270.8333 | N13: =SUM(B13:M13) -> 111250
A14: Optimista | B14: =Modelo!$G$6*$C$6*(1+$C$9)^0 - (Modelo!$G$9+Modelo!$G$10)*$C$7 - Modelo!$G$11*$C$8 - (Modelo!$G$6*$C$6*(1+$C$9)^0)*Supuestos!$B$22 -> 20460.417 | C14: =Modelo!$G$6*$C$6*(1+$C$9)^1 - (Modelo!$G$9+Modelo!$G$10)*$C$7 - Modelo!$G$11*$C$8 - (Modelo!$G$6*$C$6*(1+$C$9)^1)*Supuestos!$B$22 -> 20865.417 | D14: =Modelo!$G$6*$C$6*(1+$C$9)^2 - (Modelo!$G$9+Modelo!$G$10)*$C$7 - Modelo!$G$11*$C$8 - (Modelo!$G$6*$C$6*(1+$C$9)^2)*Supuestos!$B$22 -> 21272.442 | E14: =Modelo!$G$6*$C$6*(1+$C$9)^3 - (Modelo!$G$9+Modelo!$G$10)*$C$7 - Modelo!$G$11*$C$8 - (Modelo!$G$6*$C$6*(1+$C$9)^3)*Supuestos!$B$22 -> 21681.502 | F14: =Modelo!$G$6*$C$6*(1+$C$9)^4 - (Modelo!$G$9+Modelo!$G$10)*$C$7 - Modelo!$G$11*$C$8 - (Modelo!$G$6*$C$6*(1+$C$9)^4)*Supuestos!$B$22 -> 22092.607 | G14: =Modelo!$G$6*$C$6*(1+$C$9)^5 - (Modelo!$G$9+Modelo!$G$10)*$C$7 - Modelo!$G$11*$C$8 - (Modelo!$G$6*$C$6*(1+$C$9)^5)*Supuestos!$B$22 -> 22505.768 | H14: =Modelo!$G$6*$C$6*(1+$C$9)^6 - (Modelo!$G$9+Modelo!$G$10)*$C$7 - Modelo!$G$11*$C$8 - (Modelo!$G$6*$C$6*(1+$C$9)^6)*Supuestos!$B$22 -> 22920.995 | I14: =Modelo!$G$6*$C$6*(1+$C$9)^7 - (Modelo!$G$9+Modelo!$G$10)*$C$7 - Modelo!$G$11*$C$8 - (Modelo!$G$6*$C$6*(1+$C$9)^7)*Supuestos!$B$22 -> 23338.298 | J14: =Modelo!$G$6*$C$6*(1+$C$9)^8 - (Modelo!$G$9+Modelo!$G$10)*$C$7 - Modelo!$G$11*$C$8 - (Modelo!$G$6*$C$6*(1+$C$9)^8)*Supuestos!$B$22 -> 23757.687 | K14: =Modelo!$G$6*$C$6*(1+$C$9)^9 - (Modelo!$G$9+Modelo!$G$10)*$C$7 - Modelo!$G$11*$C$8 - (Modelo!$G$6*$C$6*(1+$C$9)^9)*Supuestos!$B$22 -> 24179.174 | L14: =Modelo!$G$6*$C$6*(1+$C$9)^10 - (Modelo!$G$9+Modelo!$G$10)*$C$7 - Modelo!$G$11*$C$8 - (Modelo!$G$6*$C$6*(1+$C$9)^10)*Supuestos!$B$22 -> 24602.767 | M14: =Modelo!$G$6*$C$6*(1+$C$9)^11 - (Modelo!$G$9+Modelo!$G$10)*$C$7 - Modelo!$G$11*$C$8 - (Modelo!$G$6*$C$6*(1+$C$9)^11)*Supuestos!$B$22 -> 25028.479 | N14: =SUM(B14:M14) -> 272705.55
A15: Pesimista | B15: =Modelo!$G$6*$D$6*(1+$D$9)^0 - (Modelo!$G$9+Modelo!$G$10)*$D$7 - Modelo!$G$11*$D$8 - (Modelo!$G$6*$D$6*(1+$D$9)^0)*Supuestos!$B$22 -> -4858.3333 | C15: =Modelo!$G$6*$D$6*(1+$D$9)^1 - (Modelo!$G$9+Modelo!$G$10)*$D$7 - Modelo!$G$11*$D$8 - (Modelo!$G$6*$D$6*(1+$D$9)^1)*Supuestos!$B$22 -> -5072.0833 | D15: =Modelo!$G$6*$D$6*(1+$D$9)^2 - (Modelo!$G$9+Modelo!$G$10)*$D$7 - Modelo!$G$11*$D$8 - (Modelo!$G$6*$D$6*(1+$D$9)^2)*Supuestos!$B$22 -> -5285.1921 | E15: =Modelo!$G$6*$D$6*(1+$D$9)^3 - (Modelo!$G$9+Modelo!$G$10)*$D$7 - Modelo!$G$11*$D$8 - (Modelo!$G$6*$D$6*(1+$D$9)^3)*Supuestos!$B$22 -> -5497.6615 | F15: =Modelo!$G$6*$D$6*(1+$D$9)^4 - (Modelo!$G$9+Modelo!$G$10)*$D$7 - Modelo!$G$11*$D$8 - (Modelo!$G$6*$D$6*(1+$D$9)^4)*Supuestos!$B$22 -> -5709.4935 | G15: =Modelo!$G$6*$D$6*(1+$D$9)^5 - (Modelo!$G$9+Modelo!$G$10)*$D$7 - Modelo!$G$11*$D$8 - (Modelo!$G$6*$D$6*(1+$D$9)^5)*Supuestos!$B$22 -> -5920.69 | H15: =Modelo!$G$6*$D$6*(1+$D$9)^6 - (Modelo!$G$9+Modelo!$G$10)*$D$7 - Modelo!$G$11*$D$8 - (Modelo!$G$6*$D$6*(1+$D$9)^6)*Supuestos!$B$22 -> -6131.253 | I15: =Modelo!$G$6*$D$6*(1+$D$9)^7 - (Modelo!$G$9+Modelo!$G$10)*$D$7 - Modelo!$G$11*$D$8 - (Modelo!$G$6*$D$6*(1+$D$9)^7)*Supuestos!$B$22 -> -6341.1842 | J15: =Modelo!$G$6*$D$6*(1+$D$9)^8 - (Modelo!$G$9+Modelo!$G$10)*$D$7 - Modelo!$G$11*$D$8 - (Modelo!$G$6*$D$6*(1+$D$9)^8)*Supuestos!$B$22 -> -6550.4857 | K15: =Modelo!$G$6*$D$6*(1+$D$9)^9 - (Modelo!$G$9+Modelo!$G$10)*$D$7 - Modelo!$G$11*$D$8 - (Modelo!$G$6*$D$6*(1+$D$9)^9)*Supuestos!$B$22 -> -6759.1592 | L15: =Modelo!$G$6*$D$6*(1+$D$9)^10 - (Modelo!$G$9+Modelo!$G$10)*$D$7 - Modelo!$G$11*$D$8 - (Modelo!$G$6*$D$6*(1+$D$9)^10)*Supuestos!$B$22 -> -6967.2067 | M15: =Modelo!$G$6*$D$6*(1+$D$9)^11 - (Modelo!$G$9+Modelo!$G$10)*$D$7 - Modelo!$G$11*$D$8 - (Modelo!$G$6*$D$6*(1+$D$9)^11)*Supuestos!$B$22 -> -7174.6301 | N15: =SUM(B15:M15) -> -72267.373
A17: MARGEN NETO MENSUAL POR CLIENTE - ESCENARIO BASE
A18: Cliente / Mes | B18: M1 | C18: M2 | D18: M3 | E18: M4 | F18: M5 | G18: M6 | H18: M7 | I18: M8 | J18: M9 | K18: M10 | L18: M11 | M18: M12 | N18: Total Año
A19: Hospital Vall d'Hebron | B19: =Modelo!$B$6*$B$6*(1+$B$9)^0 - (Modelo!$B$9+Modelo!$B$10)*$B$7 - Modelo!$B$11*$B$8 - (Modelo!$B$6*$B$6*(1+$B$9)^0)*Supuestos!$B$22 -> 1050 | C19: =Modelo!$B$6*$B$6*(1+$B$9)^1 - (Modelo!$B$9+Modelo!$B$10)*$B$7 - Modelo!$B$11*$B$8 - (Modelo!$B$6*$B$6*(1+$B$9)^1)*Supuestos!$B$22 -> 1050 | D19: =Modelo!$B$6*$B$6*(1+$B$9)^2 - (Modelo!$B$9+Modelo!$B$10)*$B$7 - Modelo!$B$11*$B$8 - (Modelo!$B$6*$B$6*(1+$B$9)^2)*Supuestos!$B$22 -> 1050 | E19: =Modelo!$B$6*$B$6*(1+$B$9)^3 - (Modelo!$B$9+Modelo!$B$10)*$B$7 - Modelo!$B$11*$B$8 - (Modelo!$B$6*$B$6*(1+$B$9)^3)*Supuestos!$B$22 -> 1050 | F19: =Modelo!$B$6*$B$6*(1+$B$9)^4 - (Modelo!$B$9+Modelo!$B$10)*$B$7 - Modelo!$B$11*$B$8 - (Modelo!$B$6*$B$6*(1+$B$9)^4)*Supuestos!$B$22 -> 1050 | G19: =Modelo!$B$6*$B$6*(1+$B$9)^5 - (Modelo!$B$9+Modelo!$B$10)*$B$7 - Modelo!$B$11*$B$8 - (Modelo!$B$6*$B$6*(1+$B$9)^5)*Supuestos!$B$22 -> 1050 | H19: =Modelo!$B$6*$B$6*(1+$B$9)^6 - (Modelo!$B$9+Modelo!$B$10)*$B$7 - Modelo!$B$11*$B$8 - (Modelo!$B$6*$B$6*(1+$B$9)^6)*Supuestos!$B$22 -> 1050 | I19: =Modelo!$B$6*$B$6*(1+$B$9)^7 - (Modelo!$B$9+Modelo!$B$10)*$B$7 - Modelo!$B$11*$B$8 - (Modelo!$B$6*$B$6*(1+$B$9)^7)*Supuestos!$B$22 -> 1050 | J19: =Modelo!$B$6*$B$6*(1+$B$9)^8 - (Modelo!$B$9+Modelo!$B$10)*$B$7 - Modelo!$B$11*$B$8 - (Modelo!$B$6*$B$6*(1+$B$9)^8)*Supuestos!$B$22 -> 1050 | K19: =Modelo!$B$6*$B$6*(1+$B$9)^9 - (Modelo!$B$9+Modelo!$B$10)*$B$7 - Modelo!$B$11*$B$8 - (Modelo!$B$6*$B$6*(1+$B$9)^9)*Supuestos!$B$22 -> 1050 | L19: =Modelo!$B$6*$B$6*(1+$B$9)^10 - (Modelo!$B$9+Modelo!$B$10)*$B$7 - Modelo!$B$11*$B$8 - (Modelo!$B$6*$B$6*(1+$B$9)^10)*Supuestos!$B$22 -> 1050 | M19: =Modelo!$B$6*$B$6*(1+$B$9)^11 - (Modelo!$B$9+Modelo!$B$10)*$B$7 - Modelo!$B$11*$B$8 - (Modelo!$B$6*$B$6*(1+$B$9)^11)*Supuestos!$B$22 -> 1050 | N19: =SUM(B19:M19) -> 12600
A20: SEAT Martorell | B20: =Modelo!$C$6*$B$6*(1+$B$9)^0 - (Modelo!$C$9+Modelo!$C$10)*$B$7 - Modelo!$C$11*$B$8 - (Modelo!$C$6*$B$6*(1+$B$9)^0)*Supuestos!$B$22 -> 2750 | C20: =Modelo!$C$6*$B$6*(1+$B$9)^1 - (Modelo!$C$9+Modelo!$C$10)*$B$7 - Modelo!$C$11*$B$8 - (Modelo!$C$6*$B$6*(1+$B$9)^1)*Supuestos!$B$22 -> 2750 | D20: =Modelo!$C$6*$B$6*(1+$B$9)^2 - (Modelo!$C$9+Modelo!$C$10)*$B$7 - Modelo!$C$11*$B$8 - (Modelo!$C$6*$B$6*(1+$B$9)^2)*Supuestos!$B$22 -> 2750 | E20: =Modelo!$C$6*$B$6*(1+$B$9)^3 - (Modelo!$C$9+Modelo!$C$10)*$B$7 - Modelo!$C$11*$B$8 - (Modelo!$C$6*$B$6*(1+$B$9)^3)*Supuestos!$B$22 -> 2750 | F20: =Modelo!$C$6*$B$6*(1+$B$9)^4 - (Modelo!$C$9+Modelo!$C$10)*$B$7 - Modelo!$C$11*$B$8 - (Modelo!$C$6*$B$6*(1+$B$9)^4)*Supuestos!$B$22 -> 2750 | G20: =Modelo!$C$6*$B$6*(1+$B$9)^5 - (Modelo!$C$9+Modelo!$C$10)*$B$7 - Modelo!$C$11*$B$8 - (Modelo!$C$6*$B$6*(1+$B$9)^5)*Supuestos!$B$22 -> 2750 | H20: =Modelo!$C$6*$B$6*(1+$B$9)^6 - (Modelo!$C$9+Modelo!$C$10)*$B$7 - Modelo!$C$11*$B$8 - (Modelo!$C$6*$B$6*(1+$B$9)^6)*Supuestos!$B$22 -> 2750 | I20: =Modelo!$C$6*$B$6*(1+$B$9)^7 - (Modelo!$C$9+Modelo!$C$10)*$B$7 - Modelo!$C$11*$B$8 - (Modelo!$C$6*$B$6*(1+$B$9)^7)*Supuestos!$B$22 -> 2750 | J20: =Modelo!$C$6*$B$6*(1+$B$9)^8 - (Modelo!$C$9+Modelo!$C$10)*$B$7 - Modelo!$C$11*$B$8 - (Modelo!$C$6*$B$6*(1+$B$9)^8)*Supuestos!$B$22 -> 2750 | K20: =Modelo!$C$6*$B$6*(1+$B$9)^9 - (Modelo!$C$9+Modelo!$C$10)*$B$7 - Modelo!$C$11*$B$8 - (Modelo!$C$6*$B$6*(1+$B$9)^9)*Supuestos!$B$22 -> 2750 | L20: =Modelo!$C$6*$B$6*(1+$B$9)^10 - (Modelo!$C$9+Modelo!$C$10)*$B$7 - Modelo!$C$11*$B$8 - (Modelo!$C$6*$B$6*(1+$B$9)^10)*Supuestos!$B$22 -> 2750 | M20: =Modelo!$C$6*$B$6*(1+$B$9)^11 - (Modelo!$C$9+Modelo!$C$10)*$B$7 - Modelo!$C$11*$B$8 - (Modelo!$C$6*$B$6*(1+$B$9)^11)*Supuestos!$B$22 -> 2750 | N20: =SUM(B20:M20) -> 33000
A21: UAB Bellaterra | B21: =Modelo!$D$6*$B$6*(1+$B$9)^0 - (Modelo!$D$9+Modelo!$D$10)*$B$7 - Modelo!$D$11*$B$8 - (Modelo!$D$6*$B$6*(1+$B$9)^0)*Supuestos!$B$22 -> 1737.5 | C21: =Modelo!$D$6*$B$6*(1+$B$9)^1 - (Modelo!$D$9+Modelo!$D$10)*$B$7 - Modelo!$D$11*$B$8 - (Modelo!$D$6*$B$6*(1+$B$9)^1)*Supuestos!$B$22 -> 1737.5 | D21: =Modelo!$D$6*$B$6*(1+$B$9)^2 - (Modelo!$D$9+Modelo!$D$10)*$B$7 - Modelo!$D$11*$B$8 - (Modelo!$D$6*$B$6*(1+$B$9)^2)*Supuestos!$B$22 -> 1737.5 | E21: =Modelo!$D$6*$B$6*(1+$B$9)^3 - (Modelo!$D$9+Modelo!$D$10)*$B$7 - Modelo!$D$11*$B$8 - (Modelo!$D$6*$B$6*(1+$B$9)^3)*Supuestos!$B$22 -> 1737.5 | F21: =Modelo!$D$6*$B$6*(1+$B$9)^4 - (Modelo!$D$9+Modelo!$D$10)*$B$7 - Modelo!$D$11*$B$8 - (Modelo!$D$6*$B$6*(1+$B$9)^4)*Supuestos!$B$22 -> 1737.5 | G21: =Modelo!$D$6*$B$6*(1+$B$9)^5 - (Modelo!$D$9+Modelo!$D$10)*$B$7 - Modelo!$D$11*$B$8 - (Modelo!$D$6*$B$6*(1+$B$9)^5)*Supuestos!$B$22 -> 1737.5 | H21: =Modelo!$D$6*$B$6*(1+$B$9)^6 - (Modelo!$D$9+Modelo!$D$10)*$B$7 - Modelo!$D$11*$B$8 - (Modelo!$D$6*$B$6*(1+$B$9)^6)*Supuestos!$B$22 -> 1737.5 | I21: =Modelo!$D$6*$B$6*(1+$B$9)^7 - (Modelo!$D$9+Modelo!$D$10)*$B$7 - Modelo!$D$11*$B$8 - (Modelo!$D$6*$B$6*(1+$B$9)^7)*Supuestos!$B$22 -> 1737.5 | J21: =Modelo!$D$6*$B$6*(1+$B$9)^8 - (Modelo!$D$9+Modelo!$D$10)*$B$7 - Modelo!$D$11*$B$8 - (Modelo!$D$6*$B$6*(1+$B$9)^8)*Supuestos!$B$22 -> 1737.5 | K21: =Modelo!$D$6*$B$6*(1+$B$9)^9 - (Modelo!$D$9+Modelo!$D$10)*$B$7 - Modelo!$D$11*$B$8 - (Modelo!$D$6*$B$6*(1+$B$9)^9)*Supuestos!$B$22 -> 1737.5 | L21: =Modelo!$D$6*$B$6*(1+$B$9)^10 - (Modelo!$D$9+Modelo!$D$10)*$B$7 - Modelo!$D$11*$B$8 - (Modelo!$D$6*$B$6*(1+$B$9)^10)*Supuestos!$B$22 -> 1737.5 | M21: =Modelo!$D$6*$B$6*(1+$B$9)^11 - (Modelo!$D$9+Modelo!$D$10)*$B$7 - Modelo!$D$11*$B$8 - (Modelo!$D$6*$B$6*(1+$B$9)^11)*Supuestos!$B$22 -> 1737.5 | N21: =SUM(B21:M21) -> 20850
A22: Danone Parets | B22: =Modelo!$E$6*$B$6*(1+$B$9)^0 - (Modelo!$E$9+Modelo!$E$10)*$B$7 - Modelo!$E$11*$B$8 - (Modelo!$E$6*$B$6*(1+$B$9)^0)*Supuestos!$B$22 -> 1041.6667 | C22: =Modelo!$E$6*$B$6*(1+$B$9)^1 - (Modelo!$E$9+Modelo!$E$10)*$B$7 - Modelo!$E$11*$B$8 - (Modelo!$E$6*$B$6*(1+$B$9)^1)*Supuestos!$B$22 -> 1041.6667 | D22: =Modelo!$E$6*$B$6*(1+$B$9)^2 - (Modelo!$E$9+Modelo!$E$10)*$B$7 - Modelo!$E$11*$B$8 - (Modelo!$E$6*$B$6*(1+$B$9)^2)*Supuestos!$B$22 -> 1041.6667 | E22: =Modelo!$E$6*$B$6*(1+$B$9)^3 - (Modelo!$E$9+Modelo!$E$10)*$B$7 - Modelo!$E$11*$B$8 - (Modelo!$E$6*$B$6*(1+$B$9)^3)*Supuestos!$B$22 -> 1041.6667 | F22: =Modelo!$E$6*$B$6*(1+$B$9)^4 - (Modelo!$E$9+Modelo!$E$10)*$B$7 - Modelo!$E$11*$B$8 - (Modelo!$E$6*$B$6*(1+$B$9)^4)*Supuestos!$B$22 -> 1041.6667 | G22: =Modelo!$E$6*$B$6*(1+$B$9)^5 - (Modelo!$E$9+Modelo!$E$10)*$B$7 - Modelo!$E$11*$B$8 - (Modelo!$E$6*$B$6*(1+$B$9)^5)*Supuestos!$B$22 -> 1041.6667 | H22: =Modelo!$E$6*$B$6*(1+$B$9)^6 - (Modelo!$E$9+Modelo!$E$10)*$B$7 - Modelo!$E$11*$B$8 - (Modelo!$E$6*$B$6*(1+$B$9)^6)*Supuestos!$B$22 -> 1041.6667 | I22: =Modelo!$E$6*$B$6*(1+$B$9)^7 - (Modelo!$E$9+Modelo!$E$10)*$B$7 - Modelo!$E$11*$B$8 - (Modelo!$E$6*$B$6*(1+$B$9)^7)*Supuestos!$B$22 -> 1041.6667 | J22: =Modelo!$E$6*$B$6*(1+$B$9)^8 - (Modelo!$E$9+Modelo!$E$10)*$B$7 - Modelo!$E$11*$B$8 - (Modelo!$E$6*$B$6*(1+$B$9)^8)*Supuestos!$B$22 -> 1041.6667 | K22: =Modelo!$E$6*$B$6*(1+$B$9)^9 - (Modelo!$E$9+Modelo!$E$10)*$B$7 - Modelo!$E$11*$B$8 - (Modelo!$E$6*$B$6*(1+$B$9)^9)*Supuestos!$B$22 -> 1041.6667 | L22: =Modelo!$E$6*$B$6*(1+$B$9)^10 - (Modelo!$E$9+Modelo!$E$10)*$B$7 - Modelo!$E$11*$B$8 - (Modelo!$E$6*$B$6*(1+$B$9)^10)*Supuestos!$B$22 -> 1041.6667 | M22: =Modelo!$E$6*$B$6*(1+$B$9)^11 - (Modelo!$E$9+Modelo!$E$10)*$B$7 - Modelo!$E$11*$B$8 - (Modelo!$E$6*$B$6*(1+$B$9)^11)*Supuestos!$B$22 -> 1041.6667 | N22: =SUM(B22:M22) -> 12500
A23: CCCB Barcelona | B23: =Modelo!$F$6*$B$6*(1+$B$9)^0 - (Modelo!$F$9+Modelo!$F$10)*$B$7 - Modelo!$F$11*$B$8 - (Modelo!$F$6*$B$6*(1+$B$9)^0)*Supuestos!$B$22 -> 2691.6667 | C23: =Modelo!$F$6*$B$6*(1+$B$9)^1 - (Modelo!$F$9+Modelo!$F$10)*$B$7 - Modelo!$F$11*$B$8 - (Modelo!$F$6*$B$6*(1+$B$9)^1)*Supuestos!$B$22 -> 2691.6667 | D23: =Modelo!$F$6*$B$6*(1+$B$9)^2 - (Modelo!$F$9+Modelo!$F$10)*$B$7 - Modelo!$F$11*$B$8 - (Modelo!$F$6*$B$6*(1+$B$9)^2)*Supuestos!$B$22 -> 2691.6667 | E23: =Modelo!$F$6*$B$6*(1+$B$9)^3 - (Modelo!$F$9+Modelo!$F$10)*$B$7 - Modelo!$F$11*$B$8 - (Modelo!$F$6*$B$6*(1+$B$9)^3)*Supuestos!$B$22 -> 2691.6667 | F23: =Modelo!$F$6*$B$6*(1+$B$9)^4 - (Modelo!$F$9+Modelo!$F$10)*$B$7 - Modelo!$F$11*$B$8 - (Modelo!$F$6*$B$6*(1+$B$9)^4)*Supuestos!$B$22 -> 2691.6667 | G23: =Modelo!$F$6*$B$6*(1+$B$9)^5 - (Modelo!$F$9+Modelo!$F$10)*$B$7 - Modelo!$F$11*$B$8 - (Modelo!$F$6*$B$6*(1+$B$9)^5)*Supuestos!$B$22 -> 2691.6667 | H23: =Modelo!$F$6*$B$6*(1+$B$9)^6 - (Modelo!$F$9+Modelo!$F$10)*$B$7 - Modelo!$F$11*$B$8 - (Modelo!$F$6*$B$6*(1+$B$9)^6)*Supuestos!$B$22 -> 2691.6667 | I23: =Modelo!$F$6*$B$6*(1+$B$9)^7 - (Modelo!$F$9+Modelo!$F$10)*$B$7 - Modelo!$F$11*$B$8 - (Modelo!$F$6*$B$6*(1+$B$9)^7)*Supuestos!$B$22 -> 2691.6667 | J23: =Modelo!$F$6*$B$6*(1+$B$9)^8 - (Modelo!$F$9+Modelo!$F$10)*$B$7 - Modelo!$F$11*$B$8 - (Modelo!$F$6*$B$6*(1+$B$9)^8)*Supuestos!$B$22 -> 2691.6667 | K23: =Modelo!$F$6*$B$6*(1+$B$9)^9 - (Modelo!$F$9+Modelo!$F$10)*$B$7 - Modelo!$F$11*$B$8 - (Modelo!$F$6*$B$6*(1+$B$9)^9)*Supuestos!$B$22 -> 2691.6667 | L23: =Modelo!$F$6*$B$6*(1+$B$9)^10 - (Modelo!$F$9+Modelo!$F$10)*$B$7 - Modelo!$F$11*$B$8 - (Modelo!$F$6*$B$6*(1+$B$9)^10)*Supuestos!$B$22 -> 2691.6667 | M23: =Modelo!$F$6*$B$6*(1+$B$9)^11 - (Modelo!$F$9+Modelo!$F$10)*$B$7 - Modelo!$F$11*$B$8 - (Modelo!$F$6*$B$6*(1+$B$9)^11)*Supuestos!$B$22 -> 2691.6667 | N23: =SUM(B23:M23) -> 32300
A24: TOTAL CONSOLIDADO | B24: =SUM(B19:B23) -> 9270.8333 | C24: =SUM(C19:C23) -> 9270.8333 | D24: =SUM(D19:D23) -> 9270.8333 | E24: =SUM(E19:E23) -> 9270.8333 | F24: =SUM(F19:F23) -> 9270.8333 | G24: =SUM(G19:G23) -> 9270.8333 | H24: =SUM(H19:H23) -> 9270.8333 | I24: =SUM(I19:I23) -> 9270.8333 | ... M24: =SUM(M19:M23) -> 9270.8333 | N24: =SUM(B24:M24) -> 111250
A26: MARGEN NETO MENSUAL POR CLIENTE - ESCENARIO OPTIMISTA
A27: Cliente / Mes | B27: M1 | C27: M2 | D27: M3 | E27: M4 | F27: M5 | G27: M6 | H27: M7 | I27: M8 | J27: M9 | K27: M10 | L27: M11 | M27: M12 | N27: Total Año
A28: Hospital Vall d'Hebron | B28: =Modelo!$B$6*$C$6*(1+$C$9)^0 - (Modelo!$B$9+Modelo!$B$10)*$C$7 - Modelo!$B$11*$C$8 - (Modelo!$B$6*$C$6*(1+$C$9)^0)*Supuestos!$B$22 -> 5737.5 | C28: =Modelo!$B$6*$C$6*(1+$C$9)^1 - (Modelo!$B$9+Modelo!$B$10)*$C$7 - Modelo!$B$11*$C$8 - (Modelo!$B$6*$C$6*(1+$C$9)^1)*Supuestos!$B$22 -> 5899.5 | D28: =Modelo!$B$6*$C$6*(1+$C$9)^2 - (Modelo!$B$9+Modelo!$B$10)*$C$7 - Modelo!$B$11*$C$8 - (Modelo!$B$6*$C$6*(1+$C$9)^2)*Supuestos!$B$22 -> 6062.31 | E28: =Modelo!$B$6*$C$6*(1+$C$9)^3 - (Modelo!$B$9+Modelo!$B$10)*$C$7 - Modelo!$B$11*$C$8 - (Modelo!$B$6*$C$6*(1+$C$9)^3)*Supuestos!$B$22 -> 6225.934 | F28: =Modelo!$B$6*$C$6*(1+$C$9)^4 - (Modelo!$B$9+Modelo!$B$10)*$C$7 - Modelo!$B$11*$C$8 - (Modelo!$B$6*$C$6*(1+$C$9)^4)*Supuestos!$B$22 -> 6390.3762 | G28: =Modelo!$B$6*$C$6*(1+$C$9)^5 - (Modelo!$B$9+Modelo!$B$10)*$C$7 - Modelo!$B$11*$C$8 - (Modelo!$B$6*$C$6*(1+$C$9)^5)*Supuestos!$B$22 -> 6555.6406 | H28: =Modelo!$B$6*$C$6*(1+$C$9)^6 - (Modelo!$B$9+Modelo!$B$10)*$C$7 - Modelo!$B$11*$C$8 - (Modelo!$B$6*$C$6*(1+$C$9)^6)*Supuestos!$B$22 -> 6721.7313 | I28: =Modelo!$B$6*$C$6*(1+$C$9)^7 - (Modelo!$B$9+Modelo!$B$10)*$C$7 - Modelo!$B$11*$C$8 - (Modelo!$B$6*$C$6*(1+$C$9)^7)*Supuestos!$B$22 -> 6888.6525 | J28: =Modelo!$B$6*$C$6*(1+$C$9)^8 - (Modelo!$B$9+Modelo!$B$10)*$C$7 - Modelo!$B$11*$C$8 - (Modelo!$B$6*$C$6*(1+$C$9)^8)*Supuestos!$B$22 -> 7056.4082 | K28: =Modelo!$B$6*$C$6*(1+$C$9)^9 - (Modelo!$B$9+Modelo!$B$10)*$C$7 - Modelo!$B$11*$C$8 - (Modelo!$B$6*$C$6*(1+$C$9)^9)*Supuestos!$B$22 -> 7225.0028 | L28: =Modelo!$B$6*$C$6*(1+$C$9)^10 - (Modelo!$B$9+Modelo!$B$10)*$C$7 - Modelo!$B$11*$C$8 - (Modelo!$B$6*$C$6*(1+$C$9)^10)*Supuestos!$B$22 -> 7394.4403 | M28: =Modelo!$B$6*$C$6*(1+$C$9)^11 - (Modelo!$B$9+Modelo!$B$10)*$C$7 - Modelo!$B$11*$C$8 - (Modelo!$B$6*$C$6*(1+$C$9)^11)*Supuestos!$B$22 -> 7564.725 | N28: =SUM(B28:M28) -> 79722.221
A29: SEAT Martorell | B29: =Modelo!$C$6*$C$6*(1+$C$9)^0 - (Modelo!$C$9+Modelo!$C$10)*$C$7 - Modelo!$C$11*$C$8 - (Modelo!$C$6*$C$6*(1+$C$9)^0)*Supuestos!$B$22 -> 5826.6667 | C29: =Modelo!$C$6*$C$6*(1+$C$9)^1 - (Modelo!$C$9+Modelo!$C$10)*$C$7 - Modelo!$C$11*$C$8 - (Modelo!$C$6*$C$6*(1+$C$9)^1)*Supuestos!$B$22 -> 5927.4667 | D29: =Modelo!$C$6*$C$6*(1+$C$9)^2 - (Modelo!$C$9+Modelo!$C$10)*$C$7 - Modelo!$C$11*$C$8 - (Modelo!$C$6*$C$6*(1+$C$9)^2)*Supuestos!$B$22 -> 6028.7707 | E29: =Modelo!$C$6*$C$6*(1+$C$9)^3 - (Modelo!$C$9+Modelo!$C$10)*$C$7 - Modelo!$C$11*$C$8 - (Modelo!$C$6*$C$6*(1+$C$9)^3)*Supuestos!$B$22 -> 6130.5812 | F29: =Modelo!$C$6*$C$6*(1+$C$9)^4 - (Modelo!$C$9+Modelo!$C$10)*$C$7 - Modelo!$C$11*$C$8 - (Modelo!$C$6*$C$6*(1+$C$9)^4)*Supuestos!$B$22 -> 6232.9008 | G29: =Modelo!$C$6*$C$6*(1+$C$9)^5 - (Modelo!$C$9+Modelo!$C$10)*$C$7 - Modelo!$C$11*$C$8 - (Modelo!$C$6*$C$6*(1+$C$9)^5)*Supuestos!$B$22 -> 6335.7319 | H29: =Modelo!$C$6*$C$6*(1+$C$9)^6 - (Modelo!$C$9+Modelo!$C$10)*$C$7 - Modelo!$C$11*$C$8 - (Modelo!$C$6*$C$6*(1+$C$9)^6)*Supuestos!$B$22 -> 6439.0773 | I29: =Modelo!$C$6*$C$6*(1+$C$9)^7 - (Modelo!$C$9+Modelo!$C$10)*$C$7 - Modelo!$C$11*$C$8 - (Modelo!$C$6*$C$6*(1+$C$9)^7)*Supuestos!$B$22 -> 6542.9393 | J29: =Modelo!$C$6*$C$6*(1+$C$9)^8 - (Modelo!$C$9+Modelo!$C$10)*$C$7 - Modelo!$C$11*$C$8 - (Modelo!$C$6*$C$6*(1+$C$9)^8)*Supuestos!$B$22 -> 6647.3207 | K29: =Modelo!$C$6*$C$6*(1+$C$9)^9 - (Modelo!$C$9+Modelo!$C$10)*$C$7 - Modelo!$C$11*$C$8 - (Modelo!$C$6*$C$6*(1+$C$9)^9)*Supuestos!$B$22 -> 6752.2239 | L29: =Modelo!$C$6*$C$6*(1+$C$9)^10 - (Modelo!$C$9+Modelo!$C$10)*$C$7 - Modelo!$C$11*$C$8 - (Modelo!$C$6*$C$6*(1+$C$9)^10)*Supuestos!$B$22 -> 6857.6517 | M29: =Modelo!$C$6*$C$6*(1+$C$9)^11 - (Modelo!$C$9+Modelo!$C$10)*$C$7 - Modelo!$C$11*$C$8 - (Modelo!$C$6*$C$6*(1+$C$9)^11)*Supuestos!$B$22 -> 6963.6067 | N29: =SUM(B29:M29) -> 76684.937
A30: UAB Bellaterra | B30: =Modelo!$D$6*$C$6*(1+$C$9)^0 - (Modelo!$D$9+Modelo!$D$10)*$C$7 - Modelo!$D$11*$C$8 - (Modelo!$D$6*$C$6*(1+$C$9)^0)*Supuestos!$B$22 -> 3328.75 | C30: =Modelo!$D$6*$C$6*(1+$C$9)^1 - (Modelo!$D$9+Modelo!$D$10)*$C$7 - Modelo!$D$11*$C$8 - (Modelo!$D$6*$C$6*(1+$C$9)^1)*Supuestos!$B$22 -> 3393.55 | D30: =Modelo!$D$6*$C$6*(1+$C$9)^2 - (Modelo!$D$9+Modelo!$D$10)*$C$7 - Modelo!$D$11*$C$8 - (Modelo!$D$6*$C$6*(1+$C$9)^2)*Supuestos!$B$22 -> 3458.674 | E30: =Modelo!$D$6*$C$6*(1+$C$9)^3 - (Modelo!$D$9+Modelo!$D$10)*$C$7 - Modelo!$D$11*$C$8 - (Modelo!$D$6*$C$6*(1+$C$9)^3)*Supuestos!$B$22 -> 3524.1236 | F30: =Modelo!$D$6*$C$6*(1+$C$9)^4 - (Modelo!$D$9+Modelo!$D$10)*$C$7 - Modelo!$D$11*$C$8 - (Modelo!$D$6*$C$6*(1+$C$9)^4)*Supuestos!$B$22 -> 3589.9005 | G30: =Modelo!$D$6*$C$6*(1+$C$9)^5 - (Modelo!$D$9+Modelo!$D$10)*$C$7 - Modelo!$D$11*$C$8 - (Modelo!$D$6*$C$6*(1+$C$9)^5)*Supuestos!$B$22 -> 3656.0062 | H30: =Modelo!$D$6*$C$6*(1+$C$9)^6 - (Modelo!$D$9+Modelo!$D$10)*$C$7 - Modelo!$D$11*$C$8 - (Modelo!$D$6*$C$6*(1+$C$9)^6)*Supuestos!$B$22 -> 3722.4425 | I30: =Modelo!$D$6*$C$6*(1+$C$9)^7 - (Modelo!$D$9+Modelo!$D$10)*$C$7 - Modelo!$D$11*$C$8 - (Modelo!$D$6*$C$6*(1+$C$9)^7)*Supuestos!$B$22 -> 3789.211 | J30: =Modelo!$D$6*$C$6*(1+$C$9)^8 - (Modelo!$D$9+Modelo!$D$10)*$C$7 - Modelo!$D$11*$C$8 - (Modelo!$D$6*$C$6*(1+$C$9)^8)*Supuestos!$B$22 -> 3856.3133 | K30: =Modelo!$D$6*$C$6*(1+$C$9)^9 - (Modelo!$D$9+Modelo!$D$10)*$C$7 - Modelo!$D$11*$C$8 - (Modelo!$D$6*$C$6*(1+$C$9)^9)*Supuestos!$B$22 -> 3923.7511 | L30: =Modelo!$D$6*$C$6*(1+$C$9)^10 - (Modelo!$D$9+Modelo!$D$10)*$C$7 - Modelo!$D$11*$C$8 - (Modelo!$D$6*$C$6*(1+$C$9)^10)*Supuestos!$B$22 -> 3991.5261 | M30: =Modelo!$D$6*$C$6*(1+$C$9)^11 - (Modelo!$D$9+Modelo!$D$10)*$C$7 - Modelo!$D$11*$C$8 - (Modelo!$D$6*$C$6*(1+$C$9)^11)*Supuestos!$B$22 -> 4059.64 | N30: =SUM(B30:M30) -> 44293.888
A31: Danone Parets | B31: =Modelo!$E$6*$C$6*(1+$C$9)^0 - (Modelo!$E$9+Modelo!$E$10)*$C$7 - Modelo!$E$11*$C$8 - (Modelo!$E$6*$C$6*(1+$C$9)^0)*Supuestos!$B$22 -> 2160.8333 | C31: =Modelo!$E$6*$C$6*(1+$C$9)^1 - (Modelo!$E$9+Modelo!$E$10)*$C$7 - Modelo!$E$11*$C$8 - (Modelo!$E$6*$C$6*(1+$C$9)^1)*Supuestos!$B$22 -> 2204.0333 | D31: =Modelo!$E$6*$C$6*(1+$C$9)^2 - (Modelo!$E$9+Modelo!$E$10)*$C$7 - Modelo!$E$11*$C$8 - (Modelo!$E$6*$C$6*(1+$C$9)^2)*Supuestos!$B$22 -> 2247.4493 | E31: =Modelo!$E$6*$C$6*(1+$C$9)^3 - (Modelo!$E$9+Modelo!$E$10)*$C$7 - Modelo!$E$11*$C$8 - (Modelo!$E$6*$C$6*(1+$C$9)^3)*Supuestos!$B$22 -> 2291.0824 | F31: =Modelo!$E$6*$C$6*(1+$C$9)^4 - (Modelo!$E$9+Modelo!$E$10)*$C$7 - Modelo!$E$11*$C$8 - (Modelo!$E$6*$C$6*(1+$C$9)^4)*Supuestos!$B$22 -> 2334.9337 | G31: =Modelo!$E$6*$C$6*(1+$C$9)^5 - (Modelo!$E$9+Modelo!$E$10)*$C$7 - Modelo!$E$11*$C$8 - (Modelo!$E$6*$C$6*(1+$C$9)^5)*Supuestos!$B$22 -> 2379.0042 | H31: =Modelo!$E$6*$C$6*(1+$C$9)^6 - (Modelo!$E$9+Modelo!$E$10)*$C$7 - Modelo!$E$11*$C$8 - (Modelo!$E$6*$C$6*(1+$C$9)^6)*Supuestos!$B$22 -> 2423.295 | I31: =Modelo!$E$6*$C$6*(1+$C$9)^7 - (Modelo!$E$9+Modelo!$E$10)*$C$7 - Modelo!$E$11*$C$8 - (Modelo!$E$6*$C$6*(1+$C$9)^7)*Supuestos!$B$22 -> 2467.8073 | J31: =Modelo!$E$6*$C$6*(1+$C$9)^8 - (Modelo!$E$9+Modelo!$E$10)*$C$7 - Modelo!$E$11*$C$8 - (Modelo!$E$6*$C$6*(1+$C$9)^8)*Supuestos!$B$22 -> 2512.5422 | K31: =Modelo!$E$6*$C$6*(1+$C$9)^9 - (Modelo!$E$9+Modelo!$E$10)*$C$7 - Modelo!$E$11*$C$8 - (Modelo!$E$6*$C$6*(1+$C$9)^9)*Supuestos!$B$22 -> 2557.5007 | L31: =Modelo!$E$6*$C$6*(1+$C$9)^10 - (Modelo!$E$9+Modelo!$E$10)*$C$7 - Modelo!$E$11*$C$8 - (Modelo!$E$6*$C$6*(1+$C$9)^10)*Supuestos!$B$22 -> 2602.6841 | M31: =Modelo!$E$6*$C$6*(1+$C$9)^11 - (Modelo!$E$9+Modelo!$E$10)*$C$7 - Modelo!$E$11*$C$8 - (Modelo!$E$6*$C$6*(1+$C$9)^11)*Supuestos!$B$22 -> 2648.0933 | N31: =SUM(B31:M31) -> 28829.259
A32: CCCB Barcelona | B32: =Modelo!$F$6*$C$6*(1+$C$9)^0 - (Modelo!$F$9+Modelo!$F$10)*$C$7 - Modelo!$F$11*$C$8 - (Modelo!$F$6*$C$6*(1+$C$9)^0)*Supuestos!$B$22 -> 3406.6667 | C32: =Modelo!$F$6*$C$6*(1+$C$9)^1 - (Modelo!$F$9+Modelo!$F$10)*$C$7 - Modelo!$F$11*$C$8 - (Modelo!$F$6*$C$6*(1+$C$9)^1)*Supuestos!$B$22 -> 3440.8667 | D32: =Modelo!$F$6*$C$6*(1+$C$9)^2 - (Modelo!$F$9+Modelo!$F$10)*$C$7 - Modelo!$F$11*$C$8 - (Modelo!$F$6*$C$6*(1+$C$9)^2)*Supuestos!$B$22 -> 3475.2377 | E32: =Modelo!$F$6*$C$6*(1+$C$9)^3 - (Modelo!$F$9+Modelo!$F$10)*$C$7 - Modelo!$F$11*$C$8 - (Modelo!$F$6*$C$6*(1+$C$9)^3)*Supuestos!$B$22 -> 3509.7805 | F32: =Modelo!$F$6*$C$6*(1+$C$9)^4 - (Modelo!$F$9+Modelo!$F$10)*$C$7 - Modelo!$F$11*$C$8 - (Modelo!$F$6*$C$6*(1+$C$9)^4)*Supuestos!$B$22 -> 3544.4961 | G32: =Modelo!$F$6*$C$6*(1+$C$9)^5 - (Modelo!$F$9+Modelo!$F$10)*$C$7 - Modelo!$F$11*$C$8 - (Modelo!$F$6*$C$6*(1+$C$9)^5)*Supuestos!$B$22 -> 3579.3852 | H32: =Modelo!$F$6*$C$6*(1+$C$9)^6 - (Modelo!$F$9+Modelo!$F$10)*$C$7 - Modelo!$F$11*$C$8 - (Modelo!$F$6*$C$6*(1+$C$9)^6)*Supuestos!$B$22 -> 3614.4488 | I32: =Modelo!$F$6*$C$6*(1+$C$9)^7 - (Modelo!$F$9+Modelo!$F$10)*$C$7 - Modelo!$F$11*$C$8 - (Modelo!$F$6*$C$6*(1+$C$9)^7)*Supuestos!$B$22 -> 3649.6877 | J32: =Modelo!$F$6*$C$6*(1+$C$9)^8 - (Modelo!$F$9+Modelo!$F$10)*$C$7 - Modelo!$F$11*$C$8 - (Modelo!$F$6*$C$6*(1+$C$9)^8)*Supuestos!$B$22 -> 3685.1028 | K32: =Modelo!$F$6*$C$6*(1+$C$9)^9 - (Modelo!$F$9+Modelo!$F$10)*$C$7 - Modelo!$F$11*$C$8 - (Modelo!$F$6*$C$6*(1+$C$9)^9)*Supuestos!$B$22 -> 3720.695 | L32: =Modelo!$F$6*$C$6*(1+$C$9)^10 - (Modelo!$F$9+Modelo!$F$10)*$C$7 - Modelo!$F$11*$C$8 - (Modelo!$F$6*$C$6*(1+$C$9)^10)*Supuestos!$B$22 -> 3756.4652 | M32: =Modelo!$F$6*$C$6*(1+$C$9)^11 - (Modelo!$F$9+Modelo!$F$10)*$C$7 - Modelo!$F$11*$C$8 - (Modelo!$F$6*$C$6*(1+$C$9)^11)*Supuestos!$B$22 -> 3792.4142 | N32: =SUM(B32:M32) -> 43175.247
A33: TOTAL CONSOLIDADO | B33: =SUM(B28:B32) -> 20460.417 | C33: =SUM(C28:C32) -> 20865.417 | D33: =SUM(D28:D32) -> 21272.442 | E33: =SUM(E28:E32) -> 21681.502 | F33: =SUM(F28:F32) -> 22092.607 | G33: =SUM(G28:G32) -> 22505.768 | H33: =SUM(H28:H32) -> 22920.995 | I33: =SUM(I28:I32) -> 23338.298 | ... M33: =SUM(M28:M32) -> 25028.479 | N33: =SUM(B33:M33) -> 272705.55
A35: MARGEN NETO MENSUAL POR CLIENTE - ESCENARIO PESIMISTA
A36: Cliente / Mes | B36: M1 | C36: M2 | D36: M3 | E36: M4 | F36: M5 | G36: M6 | H36: M7 | I36: M8 | J36: M9 | K36: M10 | L36: M11 | M36: M12 | N36: Total Año
A37: Hospital Vall d'Hebron | B37: =Modelo!$B$6*$D$6*(1+$D$9)^0 - (Modelo!$B$9+Modelo!$B$10)*$D$7 - Modelo!$B$11*$D$8 - (Modelo!$B$6*$D$6*(1+$D$9)^0)*Supuestos!$B$22 -> -5025 | C37: =Modelo!$B$6*$D$6*(1+$D$9)^1 - (Modelo!$B$9+Modelo!$B$10)*$D$7 - Modelo!$B$11*$D$8 - (Modelo!$B$6*$D$6*(1+$D$9)^1)*Supuestos!$B$22 -> -5110.5 | D37: =Modelo!$B$6*$D$6*(1+$D$9)^2 - (Modelo!$B$9+Modelo!$B$10)*$D$7 - Modelo!$B$11*$D$8 - (Modelo!$B$6*$D$6*(1+$D$9)^2)*Supuestos!$B$22 -> -5195.7435 | E37: =Modelo!$B$6*$D$6*(1+$D$9)^3 - (Modelo!$B$9+Modelo!$B$10)*$D$7 - Modelo!$B$11*$D$8 - (Modelo!$B$6*$D$6*(1+$D$9)^3)*Supuestos!$B$22 -> -5280.7313 | F37: =Modelo!$B$6*$D$6*(1+$D$9)^4 - (Modelo!$B$9+Modelo!$B$10)*$D$7 - Modelo!$B$11*$D$8 - (Modelo!$B$6*$D$6*(1+$D$9)^4)*Supuestos!$B$22 -> -5365.4641 | G37: =Modelo!$B$6*$D$6*(1+$D$9)^5 - (Modelo!$B$9+Modelo!$B$10)*$D$7 - Modelo!$B$11*$D$8 - (Modelo!$B$6*$D$6*(1+$D$9)^5)*Supuestos!$B$22 -> -5449.9427 | H37: =Modelo!$B$6*$D$6*(1+$D$9)^6 - (Modelo!$B$9+Modelo!$B$10)*$D$7 - Modelo!$B$11*$D$8 - (Modelo!$B$6*$D$6*(1+$D$9)^6)*Supuestos!$B$22 -> -5534.1679 | I37: =Modelo!$B$6*$D$6*(1+$D$9)^7 - (Modelo!$B$9+Modelo!$B$10)*$D$7 - Modelo!$B$11*$D$8 - (Modelo!$B$6*$D$6*(1+$D$9)^7)*Supuestos!$B$22 -> -5618.1404 | J37: =Modelo!$B$6*$D$6*(1+$D$9)^8 - (Modelo!$B$9+Modelo!$B$10)*$D$7 - Modelo!$B$11*$D$8 - (Modelo!$B$6*$D$6*(1+$D$9)^8)*Supuestos!$B$22 -> -5701.8609 | K37: =Modelo!$B$6*$D$6*(1+$D$9)^9 - (Modelo!$B$9+Modelo!$B$10)*$D$7 - Modelo!$B$11*$D$8 - (Modelo!$B$6*$D$6*(1+$D$9)^9)*Supuestos!$B$22 -> -5785.3303 | L37: =Modelo!$B$6*$D$6*(1+$D$9)^10 - (Modelo!$B$9+Modelo!$B$10)*$D$7 - Modelo!$B$11*$D$8 - (Modelo!$B$6*$D$6*(1+$D$9)^10)*Supuestos!$B$22 -> -5868.5494 | M37: =Modelo!$B$6*$D$6*(1+$D$9)^11 - (Modelo!$B$9+Modelo!$B$10)*$D$7 - Modelo!$B$11*$D$8 - (Modelo!$B$6*$D$6*(1+$D$9)^11)*Supuestos!$B$22 -> -5951.5187 | N37: =SUM(B37:M37) -> -65886.949
A38: SEAT Martorell | B38: =Modelo!$C$6*$D$6*(1+$D$9)^0 - (Modelo!$C$9+Modelo!$C$10)*$D$7 - Modelo!$C$11*$D$8 - (Modelo!$C$6*$D$6*(1+$D$9)^0)*Supuestos!$B$22 -> -1350 | C38: =Modelo!$C$6*$D$6*(1+$D$9)^1 - (Modelo!$C$9+Modelo!$C$10)*$D$7 - Modelo!$C$11*$D$8 - (Modelo!$C$6*$D$6*(1+$D$9)^1)*Supuestos!$B$22 -> -1403.2 | D38: =Modelo!$C$6*$D$6*(1+$D$9)^2 - (Modelo!$C$9+Modelo!$C$10)*$D$7 - Modelo!$C$11*$D$8 - (Modelo!$C$6*$D$6*(1+$D$9)^2)*Supuestos!$B$22 -> -1456.2404 | E38: =Modelo!$C$6*$D$6*(1+$D$9)^3 - (Modelo!$C$9+Modelo!$C$10)*$D$7 - Modelo!$C$11*$D$8 - (Modelo!$C$6*$D$6*(1+$D$9)^3)*Supuestos!$B$22 -> -1509.1217 | F38: =Modelo!$C$6*$D$6*(1+$D$9)^4 - (Modelo!$C$9+Modelo!$C$10)*$D$7 - Modelo!$C$11*$D$8 - (Modelo!$C$6*$D$6*(1+$D$9)^4)*Supuestos!$B$22 -> -1561.8443 | G38: =Modelo!$C$6*$D$6*(1+$D$9)^5 - (Modelo!$C$9+Modelo!$C$10)*$D$7 - Modelo!$C$11*$D$8 - (Modelo!$C$6*$D$6*(1+$D$9)^5)*Supuestos!$B$22 -> -1614.4088 | H38: =Modelo!$C$6*$D$6*(1+$D$9)^6 - (Modelo!$C$9+Modelo!$C$10)*$D$7 - Modelo!$C$11*$D$8 - (Modelo!$C$6*$D$6*(1+$D$9)^6)*Supuestos!$B$22 -> -1666.8156 | I38: =Modelo!$C$6*$D$6*(1+$D$9)^7 - (Modelo!$C$9+Modelo!$C$10)*$D$7 - Modelo!$C$11*$D$8 - (Modelo!$C$6*$D$6*(1+$D$9)^7)*Supuestos!$B$22 -> -1719.0651 | J38: =Modelo!$C$6*$D$6*(1+$D$9)^8 - (Modelo!$C$9+Modelo!$C$10)*$D$7 - Modelo!$C$11*$D$8 - (Modelo!$C$6*$D$6*(1+$D$9)^8)*Supuestos!$B$22 -> -1771.1579 | K38: =Modelo!$C$6*$D$6*(1+$D$9)^9 - (Modelo!$C$9+Modelo!$C$10)*$D$7 - Modelo!$C$11*$D$8 - (Modelo!$C$6*$D$6*(1+$D$9)^9)*Supuestos!$B$22 -> -1823.0944 | L38: =Modelo!$C$6*$D$6*(1+$D$9)^10 - (Modelo!$C$9+Modelo!$C$10)*$D$7 - Modelo!$C$11*$D$8 - (Modelo!$C$6*$D$6*(1+$D$9)^10)*Supuestos!$B$22 -> -1874.8752 | M38: =Modelo!$C$6*$D$6*(1+$D$9)^11 - (Modelo!$C$9+Modelo!$C$10)*$D$7 - Modelo!$C$11*$D$8 - (Modelo!$C$6*$D$6*(1+$D$9)^11)*Supuestos!$B$22 -> -1926.5005 | N38: =SUM(B38:M38) -> -19676.324
A39: UAB Bellaterra | B39: =Modelo!$D$6*$D$6*(1+$D$9)^0 - (Modelo!$D$9+Modelo!$D$10)*$D$7 - Modelo!$D$11*$D$8 - (Modelo!$D$6*$D$6*(1+$D$9)^0)*Supuestos!$B$22 -> -125 | C39: =Modelo!$D$6*$D$6*(1+$D$9)^1 - (Modelo!$D$9+Modelo!$D$10)*$D$7 - Modelo!$D$11*$D$8 - (Modelo!$D$6*$D$6*(1+$D$9)^1)*Supuestos!$B$22 -> -159.2 | D39: =Modelo!$D$6*$D$6*(1+$D$9)^2 - (Modelo!$D$9+Modelo!$D$10)*$D$7 - Modelo!$D$11*$D$8 - (Modelo!$D$6*$D$6*(1+$D$9)^2)*Supuestos!$B$22 -> -193.2974 | E39: =Modelo!$D$6*$D$6*(1+$D$9)^3 - (Modelo!$D$9+Modelo!$D$10)*$D$7 - Modelo!$D$11*$D$8 - (Modelo!$D$6*$D$6*(1+$D$9)^3)*Supuestos!$B$22 -> -227.29251 | F39: =Modelo!$D$6*$D$6*(1+$D$9)^4 - (Modelo!$D$9+Modelo!$D$10)*$D$7 - Modelo!$D$11*$D$8 - (Modelo!$D$6*$D$6*(1+$D$9)^4)*Supuestos!$B$22 -> -261.18563 | G39: =Modelo!$D$6*$D$6*(1+$D$9)^5 - (Modelo!$D$9+Modelo!$D$10)*$D$7 - Modelo!$D$11*$D$8 - (Modelo!$D$6*$D$6*(1+$D$9)^5)*Supuestos!$B$22 -> -294.97707 | H39: =Modelo!$D$6*$D$6*(1+$D$9)^6 - (Modelo!$D$9+Modelo!$D$10)*$D$7 - Modelo!$D$11*$D$8 - (Modelo!$D$6*$D$6*(1+$D$9)^6)*Supuestos!$B$22 -> -328.66714 | I39: =Modelo!$D$6*$D$6*(1+$D$9)^7 - (Modelo!$D$9+Modelo!$D$10)*$D$7 - Modelo!$D$11*$D$8 - (Modelo!$D$6*$D$6*(1+$D$9)^7)*Supuestos!$B$22 -> -362.25614 | J39: =Modelo!$D$6*$D$6*(1+$D$9)^8 - (Modelo!$D$9+Modelo!$D$10)*$D$7 - Modelo!$D$11*$D$8 - (Modelo!$D$6*$D$6*(1+$D$9)^8)*Supuestos!$B$22 -> -395.74437 | K39: =Modelo!$D$6*$D$6*(1+$D$9)^9 - (Modelo!$D$9+Modelo!$D$10)*$D$7 - Modelo!$D$11*$D$8 - (Modelo!$D$6*$D$6*(1+$D$9)^9)*Supuestos!$B$22 -> -429.13214 | L39: =Modelo!$D$6*$D$6*(1+$D$9)^10 - (Modelo!$D$9+Modelo!$D$10)*$D$7 - Modelo!$D$11*$D$8 - (Modelo!$D$6*$D$6*(1+$D$9)^10)*Supuestos!$B$22 -> -462.41974 | M39: =Modelo!$D$6*$D$6*(1+$D$9)^11 - (Modelo!$D$9+Modelo!$D$10)*$D$7 - Modelo!$D$11*$D$8 - (Modelo!$D$6*$D$6*(1+$D$9)^11)*Supuestos!$B$22 -> -495.60748 | N39: =SUM(B39:M39) -> -3734.7796
A40: Danone Parets | B40: =Modelo!$E$6*$D$6*(1+$D$9)^0 - (Modelo!$E$9+Modelo!$E$10)*$D$7 - Modelo!$E$11*$D$8 - (Modelo!$E$6*$D$6*(1+$D$9)^0)*Supuestos!$B$22 -> -316.66667 | C40: =Modelo!$E$6*$D$6*(1+$D$9)^1 - (Modelo!$E$9+Modelo!$E$10)*$D$7 - Modelo!$E$11*$D$8 - (Modelo!$E$6*$D$6*(1+$D$9)^1)*Supuestos!$B$22 -> -339.46667 | D40: =Modelo!$E$6*$D$6*(1+$D$9)^2 - (Modelo!$E$9+Modelo!$E$10)*$D$7 - Modelo!$E$11*$D$8 - (Modelo!$E$6*$D$6*(1+$D$9)^2)*Supuestos!$B$22 -> -362.19827 | E40: =Modelo!$E$6*$D$6*(1+$D$9)^3 - (Modelo!$E$9+Modelo!$E$10)*$D$7 - Modelo!$E$11*$D$8 - (Modelo!$E$6*$D$6*(1+$D$9)^3)*Supuestos!$B$22 -> -384.86167 | F40: =Modelo!$E$6*$D$6*(1+$D$9)^4 - (Modelo!$E$9+Modelo!$E$10)*$D$7 - Modelo!$E$11*$D$8 - (Modelo!$E$6*$D$6*(1+$D$9)^4)*Supuestos!$B$22 -> -407.45709 | G40: =Modelo!$E$6*$D$6*(1+$D$9)^5 - (Modelo!$E$9+Modelo!$E$10)*$D$7 - Modelo!$E$11*$D$8 - (Modelo!$E$6*$D$6*(1+$D$9)^5)*Supuestos!$B$22 -> -429.98472 | H40: =Modelo!$E$6*$D$6*(1+$D$9)^6 - (Modelo!$E$9+Modelo!$E$10)*$D$7 - Modelo!$E$11*$D$8 - (Modelo!$E$6*$D$6*(1+$D$9)^6)*Supuestos!$B$22 -> -452.44476 | I40: =Modelo!$E$6*$D$6*(1+$D$9)^7 - (Modelo!$E$9+Modelo!$E$10)*$D$7 - Modelo!$E$11*$D$8 - (Modelo!$E$6*$D$6*(1+$D$9)^7)*Supuestos!$B$22 -> -474.83743 | J40: =Modelo!$E$6*$D$6*(1+$D$9)^8 - (Modelo!$E$9+Modelo!$E$10)*$D$7 - Modelo!$E$11*$D$8 - (Modelo!$E$6*$D$6*(1+$D$9)^8)*Supuestos!$B$22 -> -497.16291 | K40: =Modelo!$E$6*$D$6*(1+$D$9)^9 - (Modelo!$E$9+Modelo!$E$10)*$D$7 - Modelo!$E$11*$D$8 - (Modelo!$E$6*$D$6*(1+$D$9)^9)*Supuestos!$B$22 -> -519.42143 | L40: =Modelo!$E$6*$D$6*(1+$D$9)^10 - (Modelo!$E$9+Modelo!$E$10)*$D$7 - Modelo!$E$11*$D$8 - (Modelo!$E$6*$D$6*(1+$D$9)^10)*Supuestos!$B$22 -> -541.61316 | M40: =Modelo!$E$6*$D$6*(1+$D$9)^11 - (Modelo!$E$9+Modelo!$E$10)*$D$7 - Modelo!$E$11*$D$8 - (Modelo!$E$6*$D$6*(1+$D$9)^11)*Supuestos!$B$22 -> -563.73832 | N40: =SUM(B40:M40) -> -5289.8531
A41: CCCB Barcelona | B41: =Modelo!$F$6*$D$6*(1+$D$9)^0 - (Modelo!$F$9+Modelo!$F$10)*$D$7 - Modelo!$F$11*$D$8 - (Modelo!$F$6*$D$6*(1+$D$9)^0)*Supuestos!$B$22 -> 1958.3333 | C41: =Modelo!$F$6*$D$6*(1+$D$9)^1 - (Modelo!$F$9+Modelo!$F$10)*$D$7 - Modelo!$F$11*$D$8 - (Modelo!$F$6*$D$6*(1+$D$9)^1)*Supuestos!$B$22 -> 1940.2833 | D41: =Modelo!$F$6*$D$6*(1+$D$9)^2 - (Modelo!$F$9+Modelo!$F$10)*$D$7 - Modelo!$F$11*$D$8 - (Modelo!$F$6*$D$6*(1+$D$9)^2)*Supuestos!$B$22 -> 1922.2875 | E41: =Modelo!$F$6*$D$6*(1+$D$9)^3 - (Modelo!$F$9+Modelo!$F$10)*$D$7 - Modelo!$F$11*$D$8 - (Modelo!$F$6*$D$6*(1+$D$9)^3)*Supuestos!$B$22 -> 1904.3456 | F41: =Modelo!$F$6*$D$6*(1+$D$9)^4 - (Modelo!$F$9+Modelo!$F$10)*$D$7 - Modelo!$F$11*$D$8 - (Modelo!$F$6*$D$6*(1+$D$9)^4)*Supuestos!$B$22 -> 1886.4576 | G41: =Modelo!$F$6*$D$6*(1+$D$9)^5 - (Modelo!$F$9+Modelo!$F$10)*$D$7 - Modelo!$F$11*$D$8 - (Modelo!$F$6*$D$6*(1+$D$9)^5)*Supuestos!$B$22 -> 1868.6232 | H41: =Modelo!$F$6*$D$6*(1+$D$9)^6 - (Modelo!$F$9+Modelo!$F$10)*$D$7 - Modelo!$F$11*$D$8 - (Modelo!$F$6*$D$6*(1+$D$9)^6)*Supuestos!$B$22 -> 1850.8423 | I41: =Modelo!$F$6*$D$6*(1+$D$9)^7 - (Modelo!$F$9+Modelo!$F$10)*$D$7 - Modelo!$F$11*$D$8 - (Modelo!$F$6*$D$6*(1+$D$9)^7)*Supuestos!$B$22 -> 1833.1148 | J41: =Modelo!$F$6*$D$6*(1+$D$9)^8 - (Modelo!$F$9+Modelo!$F$10)*$D$7 - Modelo!$F$11*$D$8 - (Modelo!$F$6*$D$6*(1+$D$9)^8)*Supuestos!$B$22 -> 1815.4405 | K41: =Modelo!$F$6*$D$6*(1+$D$9)^9 - (Modelo!$F$9+Modelo!$F$10)*$D$7 - Modelo!$F$11*$D$8 - (Modelo!$F$6*$D$6*(1+$D$9)^9)*Supuestos!$B$22 -> 1797.8191 | L41: =Modelo!$F$6*$D$6*(1+$D$9)^10 - (Modelo!$F$9+Modelo!$F$10)*$D$7 - Modelo!$F$11*$D$8 - (Modelo!$F$6*$D$6*(1+$D$9)^10)*Supuestos!$B$22 -> 1780.2507 | M41: =Modelo!$F$6*$D$6*(1+$D$9)^11 - (Modelo!$F$9+Modelo!$F$10)*$D$7 - Modelo!$F$11*$D$8 - (Modelo!$F$6*$D$6*(1+$D$9)^11)*Supuestos!$B$22 -> 1762.7349 | N41: =SUM(B41:M41) -> 22320.533
A42: TOTAL CONSOLIDADO | B42: =SUM(B37:B41) -> -4858.3333 | C42: =SUM(C37:C41) -> -5072.0833 | D42: =SUM(D37:D41) -> -5285.1921 | E42: =SUM(E37:E41) -> -5497.6615 | F42: =SUM(F37:F41) -> -5709.4935 | G42: =SUM(G37:G41) -> -5920.69 | H42: =SUM(H37:H41) -> -6131.253 | I42: =SUM(I37:I41) -> -6341.1842 | ... M42: =SUM(M37:M41) -> -7174.6301 | N42: =SUM(B42:M42) -> -72267.373
A44: TABLA DE SENSIBILIDAD - MARGEN NETO CONSOLIDADO ANUAL (€)
A45: Filas: Δ tasa de crecimiento ingresos anual | Columnas: Δ coste técnico (personal + urgencias) | Verde: margen positivo | Rojo: margen negativo
A47: Δ Crec \ Δ Coste | B47: -0.2 | C47: -0.15 | D47: -0.1 | E47: -0.05 | F47: 0 | G47: 0.05 | H47: 0.1 | I47: 0.15 | J47: 0.2
...
